Workbook

Sheet Instructions
A1: MYBREAKEVEN — 12-MONTH RESTAURANT BUDGET
A2: Purpose | B2: Monthly budget, monthly actuals and year-to-date variance; USD illustration only
A3: Input | B3: Replace sample budget assumptions in yellow cells; enter actuals after each month closes
A4: Important | B4: Blank actual months do not count as zero actual profits
A5: Completion | B5: Enter all actual income and cost rows, including actual zeros, before interpreting results
A6: Profit | B6: Sales less variable costs and committed expenses; not cash flow or after-tax earnings
A7: Break-even | B7: Committed expenses / contribution margin, assuming constant variable-cost ratio
A8: Comparison | B8: Annual budget spans 12 months; actual and variance sum entered months only
A9: Caution | B9: Payroll excludes employer costs when listed separately; do not double count owner compensation
A10: Example | B10: Illustrative amounts, not industry benchmarks
A11: Original page | B11: https://mybreakeven.com/blogs/restaurant-budgeting/

Sheet 12-Month Budget
A1: RESTAURANT — MONTHLY BUDGET / ACTUAL (USD)
A3: Line item | B3: Jan | C3: Feb | D3: Mar | E3: Apr | F3: May | G3: Jun | H3: Jul | I3: Aug | J3: Sep | K3: Oct | L3: Nov | M3: Dec | N3: Annual / entered months
A4: BUDGET
A5: Food sales | B5: 40500 | C5: 40950 | D5: 44100 | E5: 45000 | F5: 47250 | G5: 48150 | H5: 50400 | I5: 48600 | J5: 45900 | K5: 45450 | L5: 46800 | M5: 51750 | N5: =SUM(B5:M5)
A6: Beverage sales | B6: 13500 | C6: 13650 | D6: 14700 | E6: 15000 | F6: 15750 | G6: 16050 | H6: 16800 | I6: 16200 | J6: 15300 | K6: 15150 | L6: 15600 | M6: 17250 | N6: =SUM(B6:M6)
A7: Total sales | B7: =SUM(B5:B6) | C7: =SUM(C5:C6) | D7: =SUM(D5:D6) | E7: =SUM(E5:E6) | F7: =SUM(F5:F6) | G7: =SUM(G5:G6) | H7: =SUM(H5:H6) | I7: =SUM(I5:I6) | ... M7: =SUM(M5:M6) | N7: =SUM(B7:M7)
A8: Food and beverage COGS | B8: 16200 | C8: 16380 | D8: 17640 | E8: 18000 | F8: 18900 | G8: 19260 | H8: 20160 | I8: 19440 | J8: 18360 | K8: 18180 | L8: 18720 | M8: 20700 | N8: =SUM(B8:M8)
A9: Packaging/delivery/fees (variable) | B9: 1620 | C9: 1638 | D9: 1764 | E9: 1800 | F9: 1890 | G9: 1926 | H9: 2016 | I9: 1944 | J9: 1836 | K9: 1818 | L9: 1872 | M9: 2070 | N9: =SUM(B9:M9)
A10: Contribution | B10: =B7-SUM(B8:B9) | C10: =C7-SUM(C8:C9) | D10: =D7-SUM(D8:D9) | E10: =E7-SUM(E8:E9) | F10: =F7-SUM(F8:F9) | G10: =G7-SUM(G8:G9) | H10: =H7-SUM(H8:H9) | I10: =I7-SUM(I8:I9) | ... M10: =M7-SUM(M8:M9) | N10: =SUM(B10:M10)
A11: Guaranteed payroll | B11: 15000 | C11: 15000 | D11: 15000 | E11: 15000 | F11: 15000 | G11: 15000 | H11: 15000 | I11: 15000 | J11: 15000 | K11: 15000 | L11: 15000 | M11: 15000 | N11: =SUM(B11:M11)
A12: Employer payroll costs | B12: 1500 | C12: 1500 | D12: 1500 | E12: 1500 | F12: 1500 | G12: 1500 | H12: 1500 | I12: 1500 | J12: 1500 | K12: 1500 | L12: 1500 | M12: 1500 | N12: =SUM(B12:M12)
A13: Owner compensation | B13: 4000 | C13: 4000 | D13: 4000 | E13: 4000 | F13: 4000 | G13: 4000 | H13: 4000 | I13: 4000 | J13: 4000 | K13: 4000 | L13: 4000 | M13: 4000 | N13: =SUM(B13:M13)
A14: Occupancy | B14: 6000 | C14: 6000 | D14: 6000 | E14: 6000 | F14: 6000 | G14: 6000 | H14: 6000 | I14: 6000 | J14: 6000 | K14: 6000 | L14: 6000 | M14: 6000 | N14: =SUM(B14:M14)
A15: Utilities | B15: 1200 | C15: 1200 | D15: 1200 | E15: 1200 | F15: 1200 | G15: 1200 | H15: 1200 | I15: 1200 | J15: 1200 | K15: 1200 | L15: 1200 | M15: 1200 | N15: =SUM(B15:M15)
A16: Marketing | B16: 800 | C16: 800 | D16: 800 | E16: 800 | F16: 800 | G16: 800 | H16: 800 | I16: 800 | J16: 800 | K16: 800 | L16: 800 | M16: 800 | N16: =SUM(B16:M16)
A17: Other committed expenses | B17: 1700 | C17: 1700 | D17: 1700 | E17: 1700 | F17: 1700 | G17: 1700 | H17: 1700 | I17: 1700 | J17: 1700 | K17: 1700 | L17: 1700 | M17: 1700 | N17: =SUM(B17:M17)
A18: Committed expenses | B18: =SUM(B11:B17) | C18: =SUM(C11:C17) | D18: =SUM(D11:D17) | E18: =SUM(E11:E17) | F18: =SUM(F11:F17) | G18: =SUM(G11:G17) | H18: =SUM(H11:H17) | I18: =SUM(I11:I17) | ... M18: =SUM(M11:M17) | N18: =SUM(B18:M18)
A19: Budget operating profit | B19: =B10-B18 | C19: =C10-C18 | D19: =D10-D18 | E19: =E10-E18 | F19: =F10-F18 | G19: =G10-G18 | H19: =H10-H18 | I19: =I10-I18 | ... M19: =M10-M18 | N19: =SUM(B19:M19)
A20: Contribution margin | B20: =IF(B7=0,"",B10/B7) | C20: =IF(C7=0,"",C10/C7) | D20: =IF(D7=0,"",D10/D7) | E20: =IF(E7=0,"",E10/E7) | F20: =IF(F7=0,"",F10/F7) | G20: =IF(G7=0,"",G10/G7) | H20: =IF(H7=0,"",H10/H7) | I20: =IF(I7=0,"",I10/I7) | ... N20: =IF(N7=0,"",N10/N7)
A21: Break-even sales | B21: =IF(B7=0,"No sales",IF(B10<=0,"No positive contribution",B18/(B10/B7))) | C21: =IF(C7=0,"No sales",IF(C10<=0,"No positive contribution",C18/(C10/C7))) | D21: =IF(D7=0,"No sales",IF(D10<=0,"No positive contribution",D18/(D10/D7))) | E21: =IF(E7=0,"No sales",IF(E10<=0,"No positive contribution",E18/(E10/E7))) | F21: =IF(F7=0,"No sales",IF(F10<=0,"No positive contribution",F18/(F10/F7))) | G21: =IF(G7=0,"No sales",IF(G10<=0,"No positive contribution",G18/(G10/G7))) | H21: =IF(H7=0,"No sales",IF(H10<=0,"No positive contribution",H18/(H10/H7))) | I21: =IF(I7=0,"No sales",IF(I10<=0,"No positive contribution",I18/(I10/I7))) | ... N21: =IF(N7=0,"No sales",IF(N10<=0,"No positive contribution",N18/(N10/N7)))
A23: ACTUAL
A24: Food sales | N24: =SUM(B24:M24)
A25: Beverage sales | N25: =SUM(B25:M25)
A26: Total sales | B26: =IF(COUNT(B24:B25)=0,"",SUM(B24:B25)) | C26: =IF(COUNT(C24:C25)=0,"",SUM(C24:C25)) | D26: =IF(COUNT(D24:D25)=0,"",SUM(D24:D25)) | E26: =IF(COUNT(E24:E25)=0,"",SUM(E24:E25)) | F26: =IF(COUNT(F24:F25)=0,"",SUM(F24:F25)) | G26: =IF(COUNT(G24:G25)=0,"",SUM(G24:G25)) | H26: =IF(COUNT(H24:H25)=0,"",SUM(H24:H25)) | I26: =IF(COUNT(I24:I25)=0,"",SUM(I24:I25)) | ... M26: =IF(COUNT(M24:M25)=0,"",SUM(M24:M25)) | N26: =SUM(B26:M26)
A27: Food and beverage COGS | N27: =SUM(B27:M27)
A28: Packaging/delivery/fees (variable) | N28: =SUM(B28:M28)
A29: Contribution | B29: =IF(B26="","",B26-SUM(B27:B28)) | C29: =IF(C26="","",C26-SUM(C27:C28)) | D29: =IF(D26="","",D26-SUM(D27:D28)) | E29: =IF(E26="","",E26-SUM(E27:E28)) | F29: =IF(F26="","",F26-SUM(F27:F28)) | G29: =IF(G26="","",G26-SUM(G27:G28)) | H29: =IF(H26="","",H26-SUM(H27:H28)) | I29: =IF(I26="","",I26-SUM(I27:I28)) | ... M29: =IF(M26="","",M26-SUM(M27:M28)) | N29: =SUM(B29:M29)
A30: Guaranteed payroll | N30: =SUM(B30:M30)
A31: Employer payroll costs | N31: =SUM(B31:M31)
A32: Owner compensation | N32: =SUM(B32:M32)
A33: Occupancy | N33: =SUM(B33:M33)
A34: Utilities | N34: =SUM(B34:M34)
A35: Marketing | N35: =SUM(B35:M35)
A36: Other committed expenses | N36: =SUM(B36:M36)
A37: Committed expenses | B37: =IF(COUNT(B30:B36)=0,"",SUM(B30:B36)) | C37: =IF(COUNT(C30:C36)=0,"",SUM(C30:C36)) | D37: =IF(COUNT(D30:D36)=0,"",SUM(D30:D36)) | E37: =IF(COUNT(E30:E36)=0,"",SUM(E30:E36)) | F37: =IF(COUNT(F30:F36)=0,"",SUM(F30:F36)) | G37: =IF(COUNT(G30:G36)=0,"",SUM(G30:G36)) | H37: =IF(COUNT(H30:H36)=0,"",SUM(H30:H36)) | I37: =IF(COUNT(I30:I36)=0,"",SUM(I30:I36)) | ... M37: =IF(COUNT(M30:M36)=0,"",SUM(M30:M36)) | N37: =SUM(B37:M37)
A38: Actual operating profit | B38: =IF(OR(B26="",B37=""),"",B29-B37) | C38: =IF(OR(C26="",C37=""),"",C29-C37) | D38: =IF(OR(D26="",D37=""),"",D29-D37) | E38: =IF(OR(E26="",E37=""),"",E29-E37) | F38: =IF(OR(F26="",F37=""),"",F29-F37) | G38: =IF(OR(G26="",G37=""),"",G29-G37) | H38: =IF(OR(H26="",H37=""),"",H29-H37) | I38: =IF(OR(I26="",I37=""),"",I29-I37) | ... M38: =IF(OR(M26="",M37=""),"",M29-M37) | N38: =SUM(B38:M38)
A39: Contribution margin | B39: =IF(OR(B26="",B26=0),"",B29/B26) | C39: =IF(OR(C26="",C26=0),"",C29/C26) | D39: =IF(OR(D26="",D26=0),"",D29/D26) | E39: =IF(OR(E26="",E26=0),"",E29/E26) | F39: =IF(OR(F26="",F26=0),"",F29/F26) | G39: =IF(OR(G26="",G26=0),"",G29/G26) | H39: =IF(OR(H26="",H26=0),"",H29/H26) | I39: =IF(OR(I26="",I26=0),"",I29/I26) | ... M39: =IF(OR(M26="",M26=0),"",M29/M26) | N39: =IF(N26=0,"",N29/N26)
A40: Break-even sales | B40: =IF(B26="","",IF(B26=0,"No sales",IF(B29<=0,"No positive contribution",B37/(B29/B26)))) | C40: =IF(C26="","",IF(C26=0,"No sales",IF(C29<=0,"No positive contribution",C37/(C29/C26)))) | D40: =IF(D26="","",IF(D26=0,"No sales",IF(D29<=0,"No positive contribution",D37/(D29/D26)))) | E40: =IF(E26="","",IF(E26=0,"No sales",IF(E29<=0,"No positive contribution",E37/(E29/E26)))) | F40: =IF(F26="","",IF(F26=0,"No sales",IF(F29<=0,"No positive contribution",F37/(F29/F26)))) | G40: =IF(G26="","",IF(G26=0,"No sales",IF(G29<=0,"No positive contribution",G37/(G29/G26)))) | H40: =IF(H26="","",IF(H26=0,"No sales",IF(H29<=0,"No positive contribution",H37/(H29/H26)))) | I40: =IF(I26="","",IF(I26=0,"No sales",IF(I29<=0,"No positive contribution",I37/(I29/I26)))) | ... M40: =IF(M26="","",IF(M26=0,"No sales",IF(M29<=0,"No positive contribution",M37/(M29/M26)))) | N40: =IF(N26=0,"No sales",IF(N29<=0,"No positive contribution",N37/(N29/N26)))
A42: VARIANCE: ACTUAL MINUS BUDGET
A43: Sales | B43: =IF(B38="","",B26-B7) | C43: =IF(C38="","",C26-C7) | D43: =IF(D38="","",D26-D7) | E43: =IF(E38="","",E26-E7) | F43: =IF(F38="","",F26-F7) | G43: =IF(G38="","",G26-G7) | H43: =IF(H38="","",H26-H7) | I43: =IF(I38="","",I26-I7) | ... M43: =IF(M38="","",M26-M7) | N43: =SUM(B43:M43)
...

Sheet Dashboard
A1: RESTAURANT BUDGET — ANNUAL SUMMARY | B1: USD / ratio
A2: Budget sales | B2: ='12-Month Budget'!N7
A3: Actual sales (entered months) | B3: ='12-Month Budget'!N26
A4: Budget operating profit | B4: ='12-Month Budget'!N19
A5: Actual operating profit (entered months) | B5: ='12-Month Budget'!N38
A6: Operating profit variance (entered months) | B6: ='12-Month Budget'!N46
A7: Budget contribution margin | B7: ='12-Month Budget'!N20
A8: Actual contribution margin | B8: ='12-Month Budget'!N39
A11: Month | B11: Budget profit | C11: Actual profit | D11: Variance
A12: Jan | B12: ='12-Month Budget'!B19 | C12: ='12-Month Budget'!B38 | D12: ='12-Month Budget'!B46
A13: Feb | B13: ='12-Month Budget'!C19 | C13: ='12-Month Budget'!C38 | D13: ='12-Month Budget'!C46
A14: Mar | B14: ='12-Month Budget'!D19 | C14: ='12-Month Budget'!D38 | D14: ='12-Month Budget'!D46
A15: Apr | B15: ='12-Month Budget'!E19 | C15: ='12-Month Budget'!E38 | D15: ='12-Month Budget'!E46
A16: May | B16: ='12-Month Budget'!F19 | C16: ='12-Month Budget'!F38 | D16: ='12-Month Budget'!F46
A17: Jun | B17: ='12-Month Budget'!G19 | C17: ='12-Month Budget'!G38 | D17: ='12-Month Budget'!G46
A18: Jul | B18: ='12-Month Budget'!H19 | C18: ='12-Month Budget'!H38 | D18: ='12-Month Budget'!H46
A19: Aug | B19: ='12-Month Budget'!I19 | C19: ='12-Month Budget'!I38 | D19: ='12-Month Budget'!I46
A20: Sep | B20: ='12-Month Budget'!J19 | C20: ='12-Month Budget'!J38 | D20: ='12-Month Budget'!J46
A21: Oct | B21: ='12-Month Budget'!K19 | C21: ='12-Month Budget'!K38 | D21: ='12-Month Budget'!K46
A22: Nov | B22: ='12-Month Budget'!L19 | C22: ='12-Month Budget'!L38 | D22: ='12-Month Budget'!L46
A23: Dec | B23: ='12-Month Budget'!M19 | C23: ='12-Month Budget'!M38 | D23: ='12-Month Budget'!M46
